Workbook
Name AvailabilityStatus: PM_Lists!$K$2:$K$5
Name CadenceType: PM_Lists!$A$2:$A$6
Name ChangeStatus: PM_Lists!$G$2:$G$8
Name Criticality: PM_Lists!$E$2:$E$5
Name Decision: PM_Lists!$H$2:$H$5
Name Frequency: PM_Lists!$B$2:$B$8
Name GenericStatus: PM_Lists!$C$2:$C$5
Name ImpactLevel: PM_Lists!$J$2:$J$4
Name Priority: PM_Lists!$F$2:$F$5
Name ResourceStatus: PM_Lists!$D$2:$D$6
Name UnavailabilityType: PM_Lists!$I$2:$I$7

Sheet Project Cover Sheet
A1: Project Name
A3: Integrated Project Management Workbook | J3: RAG STATUS | L3: AMBER
A5: Project Overview | G5: Schedule & Commercials
A6: Project Name | C6: Smartsync application | G6: Start Date | I6: 45839
A7: Client | C7: Smartsync | G7: Forecast End | I7: 46142
A8: Project Manager | C8: Suseela Nookala | G8: Duration (Days) | I8: =I7-I6 -> 303
A9: Project Sponsor | C9: Ibrahim Houari | G9: Budget | I9: 60000
A10: Complexity | C10: High | G10: Benefits | I10: To build end to end integrations with PMS systems
A12: Execution Snapshot | E12: RAID Snapshot | I12: Team & Governance
A13: =MAX(COUNTIF('Project Plan'!$D:$D,"<>")-1,0) -> 23 | C13: =COUNTIF('Project Plan'!$N:$N,"Completed") -> 22 | E13: =COUNTIFS('RAID Log'!$B:$B,"Risk",'RAID Log'!$N:$N,"<>Closed") -> 1 | G13: =COUNTIFS('RAID Log'!$B:$B,"Issue",'RAID Log'!$N:$N,"<>Closed") -> 1 | I13: =MAX(COUNTA('Stakeholder Register'!$B:$B)-1,0) -> 1 | K13: =MAX(COUNTA('Resource Management Plan'!$B:$B)-1,0) -> 14
A15: Total Tasks | C15: Completed | E15: Open Risks | G15: Open Issues | I15: Stakeholders | K15: Resources
A16: =COUNTIF('Project Plan'!$N:$N,"In Progress") -> 1 | C16: =COUNTIF('Project Plan'!$P:$P,"☑")+COUNTIF('Project Plan'!$P:$P,TRUE)+COUNTIF('Project Plan'!$P:$P,1)+COUNTIF('Project Plan'!$P:$P,"Y")+COUNTIF('Project Plan'!$P:$P,"Yes")+COUNTIF('Project Plan'!$P:$P,"✔")+COUNTIF('Project Plan'!$P:$P,"☒")+COUNTIF('Project Plan'!$P:$P,"X") -> 23 | E16: =COUNTIFS('RAID Log'!$B:$B,"Dependency",'RAID Log'!$N:$N,"<>Closed") -> 17 | G16: =MAX(COUNTIF('Change Management Plan'!$D:$D,"<>")-1,0) -> 0 | I16: =MAX(COUNTA('Governance & Cadences'!$B:$B)-1,0) -> 3
A18: In Progress | C18: Tracked Milestones | E18: Open Dependencies | G18: Change Requests | I18: Cadences | K18: Report Date
A19: Quick Navigation & Notes
A20: Use this sheet as the front page of the workbook. It pulls summary fields from Project Charter and high-level counts from the core tracking tabs. | I20: Go to Project Charter | K20: Go to Project Plan
A21: Best practice: update Project Charter first, then maintain Project Plan / RAID / Stakeholder / Resource sheets. The cover sheet will reflect the latest picture.
I22: Go to RAID Dashboard | K22: Go to Risk Register
A23: Single source of truth for charter, schedule, RAID, stakeholders, resources, changes, and milestone tracking.
I24: Go to Stakeholders | K24: Go to Milestones

Sheet Project Charter
A1: ='Project Cover Sheet'!C6 -> Smartsync application
A2: Project Name: | B2: ='Project Cover Sheet'!C6 -> Smartsync application | E2: Project Manager: | F2: ='Project Cover Sheet'!C8 -> Suseela Nookala | I2: Project Sponsor: | J2: ='Project Cover Sheet'!C9 -> Ibrahim Houari
A3: Project Start Date: | B3: ='Project Cover Sheet'!I6 -> 45839 | E3: Estimated Duration: | F3: ='Project Cover Sheet'!I8 -> 303 | I3: Forecast End Date: | J3: ='Project Cover Sheet'!I7 -> 46142
A4: Estimated Budget: | B4: ='Project Cover Sheet'!I9 -> 60000 | E4: Estimated Benefits: | F4: ='Project Cover Sheet'!I10 -> To build end to end integrations with PMS systems | I4: Project Complexity: | J4: ='Project Cover Sheet'!C10 -> High
A5: Business Case: | G5: Project Deliverables:
A6: EOB Document Handling | G6: BRD ,Detailed user stories
A11: Scope: | G11: Milestones:
A12: Included | D12: Excluded | G12: ID | H12: Milestone Title | K12: Estimated Start | L12: Estimated Finish
A13: Secure web-based application architecture hosted on AWS Upload and process multi-page EOB documents Manual EOB separation and export to Open Dental Integration to Open Dental software only (Cloud and On-prem Versions) Admin panel for user management and access roles KPI dashboard for clinic performance and usage analytics Email-based two-factor authentication (2FA) Temporary cloud-based storage with automatic deletion policies Real Time Notifications with success, warning and errors as part EOB file upload All insurance sources are provided at the beginning of the project. Code repository hosted securely (e.g., GitHub or Firebase) Training documentation and demo environment | D13: It is not currently possible to add supplemental payments (e.g., secondary or non-procedural payments) via the Open Dental API. | H13: Project Kick Off | K13: 45809 | L13: 45809
A14: Pre-signed S3 URLs for direct file uploads (minimizing PHI exposure) End-to-end encryption (HTTPS in transit, AES-256 at rest) Strict IAM policies and role-based access control Auto-expiry lifecycle policies on AWS S3 to enforce data retention limits CloudTrail setup for access logging and audit tracking Non-production environments will be seeded with anonymized or synthetic data only | D14: The API only supports procedural payments at this time. | H14: Requirements gathering | K14: 45810 | L14: 45818
D15: Supplemental payment functionality is on the Open Dental development roadmap, and it is expected (but not guaranteed) that it will be available in a future release. | H15: Development | K15: 45819 | L15: 45902
H16: Testing (UAT,Regression) | K16: 45903 | L16: 45912
H17: Production | K17: 45915 | L17: 45915
H18: Production Maintenance | K18: 45916 | L18: 45777
A20: Top 3 Risks:
A21: ID | B21: Risk/Issue Description | D21: Risk Rating | E21: Mitigation/Action Plan
D22: HIGH
D23: MEDIUM
D24: LOW
A26: Project Approval:

Sheet Project Plan
A1: Task ID | B1: WBS | C1: Phase | D1: Task Name | E1: Task Type | F1: Predecessor ID | G1: Owner | H1: Support Team / Function | I1: Planned Start Date | J1: Planned End Date | K1: Duration (Days) | L1: Actual Start Date | M1: Actual End Date | N1: Status | O1: % Complete | P1: Add to Milestone Tracker | Q1: Baseline Start Date | R1: Baseline End Date | S1: Variance (Days) | T1: RAG Status | U1: Comments / Notes | V1: _MilestoneSeq
A2: =IF(D2="","","T-"&TEXT(ROW()-1,"000")) -> T-001 | B2: 1 | C2: Initiation | D2: Project Kickoff & Mobilization | E2: PM / Governance | G2: Suseela Nookala | H2: PMO / Leadership | I2: 45663 | J2: 45663 | K2: =IF(OR(I2="",J2=""),"",J2-I2+1) -> 1 | L2: 45663 | M2: 45663 | N2: Completed | O2: 1 | P2: TRUE | Q2: 45663 | R2: 45663 | S2: =IF(A2="","",IF(OR(R2="",J2=""),"",IF(M2<>"",M2-R2,J2-R2))) -> 0 | T2: =IF(A2="","",IF(N2="Completed","Green",IF(AND(J2<>"",TODAY()>J2),"Red",IF(AND(J2<>"",TODAY()+3>=J2),"Amber","Green")))) -> Green | V2: =IF(AND(OR($P2="☑",$P2=TRUE,$P2=1,$P2="Y",$P2="Yes",$P2="✔",$P2="☒",$P2="X"),$D2<>""),COUNTIF($P$2:$P2,"☑")+COUNTIF($P$2:$P2,TRUE)+COUNTIF($P$2:$P2,1)+COUNTIF($P$2:$P2,"Y")+COUNTIF($P$2:$P2,"Yes")+COUNTIF($P$2:$P2,"✔")+COUNTIF($P$2:$P2,"☒")+COUNTIF($P$2:$P2,"X"),"") -> 1
A3: =IF(D3="","","T-"&TEXT(ROW()-1,"000")) -> T-002 | B3: 1.1 | C3: Initiation | D3: SOW Commencement | E3: Contract / Commercial | F3: T-001 | G3: Deepak Puranam/Sai Konda | H3: PMO / Contracting | I3: 45663 | J3: 45814 | K3: =IF(OR(I3="",J3=""),"",J3-I3+1) -> 152 | L3: 45814 | M3: 45814 | N3: Completed | O3: 1 | P3: TRUE | Q3: 45814 | R3: 45814 | S3: =IF(A3="","",IF(OR(R3="",J3=""),"",IF(M3<>"",M3-R3,J3-R3))) -> 0 | T3: =IF(A3="","",IF(N3="Completed","Green",IF(AND(J3<>"",TODAY()>J3),"Red",IF(AND(J3<>"",TODAY()+3>=J3),"Amber","Green")))) -> Green | V3: =IF(AND(OR($P3="☑",$P3=TRUE,$P3=1,$P3="Y",$P3="Yes",$P3="✔",$P3="☒",$P3="X"),$D3<>""),COUNTIF($P$2:$P3,"☑")+COUNTIF($P$2:$P3,TRUE)+COUNTIF($P$2:$P3,1)+COUNTIF($P$2:$P3,"Y")+COUNTIF($P$2:$P3,"Yes")+COUNTIF($P$2:$P3,"✔")+COUNTIF($P$2:$P3,"☒")+COUNTIF($P$2:$P3,"X"),"") -> 2
A4: =IF(D4="","","T-"&TEXT(ROW()-1,"000")) -> T-003 | B4: 1.2 | C4: Planning | D4: Planning | E4: Planning / Scheduling | F4: T-002 | G4: Suseela Nookala | H4: PMO / Delivery | I4: 45997 | J4: 45786 | K4: =IF(OR(I4="",J4=""),"",J4-I4+1) -> -210 | L4: 45997 | M4: 45786 | N4: Completed | O4: 1 | P4: TRUE | Q4: 45997 | R4: 45786 | S4: =IF(A4="","",IF(OR(R4="",J4=""),"",IF(M4<>"",M4-R4,J4-R4))) -> 0 | T4: =IF(A4="","",IF(N4="Completed","Green",IF(AND(J4<>"",TODAY()>J4),"Red",IF(AND(J4<>"",TODAY()+3>=J4),"Amber","Green")))) -> Green | V4: =IF(AND(OR($P4="☑",$P4=TRUE,$P4=1,$P4="Y",$P4="Yes",$P4="✔",$P4="☒",$P4="X"),$D4<>""),COUNTIF($P$2:$P4,"☑")+COUNTIF($P$2:$P4,TRUE)+COUNTIF($P$2:$P4,1)+COUNTIF($P$2:$P4,"Y")+COUNTIF($P$2:$P4,"Yes")+COUNTIF($P$2:$P4,"✔")+COUNTIF($P$2:$P4,"☒")+COUNTIF($P$2:$P4,"X"),"") -> 3
A5: =IF(D5="","","T-"&TEXT(ROW()-1,"000")) -> T-004 | B5: 1.3 | C5: Monitoring & Control | D5: Weekly Governance & Stakeholder Reporting | E5: PM / Governance | F5: T-002 | G5: Suseela Nookala | H5: PMO / Client Governance | I5: 45992 | J5: 46183 | K5: =IF(OR(I5="",J5=""),"",J5-I5+1) -> 192 | L5: 45838 | M5: 45838 | N5: Completed | O5: 1 | P5: TRUE | Q5: 45838 | R5: 45838 | S5: =IF(A5="","",IF(OR(R5="",J5=""),"",IF(M5<>"",M5-R5,J5-R5))) -> 0 | T5: =IF(A5="","",IF(N5="Completed","Green",IF(AND(J5<>"",TODAY()>J5),"Red",IF(AND(J5<>"",TODAY()+3>=J5),"Amber","Green")))) -> Green | V5: =IF(AND(OR($P5="☑",$P5=TRUE,$P5=1,$P5="Y",$P5="Yes",$P5="✔",$P5="☒",$P5="X"),$D5<>""),COUNTIF($P$2:$P5,"☑")+COUNTIF($P$2:$P5,TRUE)+COUNTIF($P$2:$P5,1)+COUNTIF($P$2:$P5,"Y")+COUNTIF($P$2:$P5,"Yes")+COUNTIF($P$2:$P5,"✔")+COUNTIF($P$2:$P5,"☒")+COUNTIF($P$2:$P5,"X"),"") -> 4
A6: =IF(D6="","","T-"&TEXT(ROW()-1,"000")) -> T-005 | B6: 1.4 | C6: Planning | D6: Change Request Scope Realignment & Re-baselining | E6: Change Control / Scope | F6: T-003 | G6: Suseela Nookala | H6: PMO / Leadership | I6: 45722 | J6: 46129 | K6: =IF(OR(I6="",J6=""),"",J6-I6+1) -> 408 | L6: 45838 | M6: 45838 | N6: Completed | O6: 1 | P6: TRUE | Q6: 45838 | R6: 45838 | S6: =IF(A6="","",IF(OR(R6="",J6=""),"",IF(M6<>"",M6-R6,J6-R6))) -> 0 | T6: =IF(A6="","",IF(N6="Completed","Green",IF(AND(J6<>"",TODAY()>J6),"Red",IF(AND(J6<>"",TODAY()+3>=J6),"Amber","Green")))) -> Green | V6: =IF(AND(OR($P6="☑",$P6=TRUE,$P6=1,$P6="Y",$P6="Yes",$P6="✔",$P6="☒",$P6="X"),$D6<>""),COUNTIF($P$2:$P6,"☑")+COUNTIF($P$2:$P6,TRUE)+COUNTIF($P$2:$P6,1)+COUNTIF($P$2:$P6,"Y")+COUNTIF($P$2:$P6,"Yes")+COUNTIF($P$2:$P6,"✔")+COUNTIF($P$2:$P6,"☒")+COUNTIF($P$2:$P6,"X"),"") -> 5
A7: =IF(D7="","","T-"&TEXT(ROW()-1,"000")) -> T-006 | B7: 1.5 | C7: Planning | D7: Change Request Approval / Signature | E7: Change Control / Scope | F7: T-005 | G7: Ibrahim/Sai | H7: Leadership / Legal | I7: 45753 | J7: 45838 | K7: =IF(OR(I7="",J7=""),"",J7-I7+1) -> 86 | L7: 45753 | M7: 45838 | N7: Completed | O7: 1 | P7: TRUE | Q7: 45753 | R7: 45838 | S7: =IF(A7="","",IF(OR(R7="",J7=""),"",IF(M7<>"",M7-R7,J7-R7))) -> 0 | T7: =IF(A7="","",IF(N7="Completed","Green",IF(AND(J7<>"",TODAY()>J7),"Red",IF(AND(J7<>"",TODAY()+3>=J7),"Amber","Green")))) -> Green | V7: =IF(AND(OR($P7="☑",$P7=TRUE,$P7=1,$P7="Y",$P7="Yes",$P7="✔",$P7="☒",$P7="X"),$D7<>""),COUNTIF($P$2:$P7,"☑")+COUNTIF($P$2:$P7,TRUE)+COUNTIF($P$2:$P7,1)+COUNTIF($P$2:$P7,"Y")+COUNTIF($P$2:$P7,"Yes")+COUNTIF($P$2:$P7,"✔")+COUNTIF($P$2:$P7,"☒")+COUNTIF($P$2:$P7,"X"),"") -> 6
A8: =IF(D8="","","T-"&TEXT(ROW()-1,"000")) -> T-007 | B8: 2 | C8: Execution | D8: User Authentication | E8: Development | F8: T-010 | G8: Himansu Sekhar Bandha | H8: Zapcom Team | I8: 45819 | J8: 45838 | K8: =IF(OR(I8="",J8=""),"",J8-I8+1) -> 20 | L8: 45819 | M8: 45838 | N8: Completed | O8: 1 | P8: TRUE | Q8: 45819 | R8: 45838 | S8: =IF(A8="","",IF(OR(R8="",J8=""),"",IF(M8<>"",M8-R8,J8-R8))) -> 0 | T8: =IF(A8="","",IF(N8="Completed","Green",IF(AND(J8<>"",TODAY()>J8),"Red",IF(AND(J8<>"",TODAY()+3>=J8),"Amber","Green")))) -> Green | V8: =IF(AND(OR($P8="☑",$P8=TRUE,$P8=1,$P8="Y",$P8="Yes",$P8="✔",$P8="☒",$P8="X"),$D8<>""),COUNTIF($P$2:$P8,"☑")+COUNTIF($P$2:$P8,TRUE)+COUNTIF($P$2:$P8,1)+COUNTIF($P$2:$P8,"Y")+COUNTIF($P$2:$P8,"Yes")+COUNTIF($P$2:$P8,"✔")+COUNTIF($P$2:$P8,"☒")+COUNTIF($P$2:$P8,"X"),"") -> 7
A9: =IF(D9="","","T-"&TEXT(ROW()-1,"000")) -> T-008 | B9: 2.1 | C9: Execution | D9: Dashboard (Landing Screen) | E9: Development | F9: T-010 | G9: Himansu Sekhar Bandha | H9: Zapcom Team | I9: 45819 | J9: 45838 | K9: =IF(OR(I9="",J9=""),"",J9-I9+1) -> 20 | L9: 45819 | M9: 45838 | N9: Completed | O9: 1 | P9: TRUE | Q9: 45819 | R9: 45838 | S9: =IF(A9="","",IF(OR(R9="",J9=""),"",IF(M9<>"",M9-R9,J9-R9))) -> 0 | T9: =IF(A9="","",IF(N9="Completed","Green",IF(AND(J9<>"",TODAY()>J9),"Red",IF(AND(J9<>"",TODAY()+3>=J9),"Amber","Green")))) -> Green | V9: =IF(AND(OR($P9="☑",$P9=TRUE,$P9=1,$P9="Y",$P9="Yes",$P9="✔",$P9="☒",$P9="X"),$D9<>""),COUNTIF($P$2:$P9,"☑")+COUNTIF($P$2:$P9,TRUE)+COUNTIF($P$2:$P9,1)+COUNTIF($P$2:$P9,"Y")+COUNTIF($P$2:$P9,"Yes")+COUNTIF($P$2:$P9,"✔")+COUNTIF($P$2:$P9,"☒")+COUNTIF($P$2:$P9,"X"),"") -> 8
A10: =IF(D10="","","T-"&TEXT(ROW()-1,"000")) -> T-009 | B10: 2.1 | C10: Execution | D10: EOB Upload | E10: Development | F10: T-010 | G10: Himansu Sekhar Bandha | H10: Zapcom Team | I10: 45819 | J10: 45846 | K10: =IF(OR(I10="",J10=""),"",J10-I10+1) -> 28 | L10: 45819 | M10: 45846 | N10: Completed | O10: 1 | P10: TRUE | Q10: 45819 | R10: 45846 | S10: =IF(A10="","",IF(OR(R10="",J10=""),"",IF(M10<>"",M10-R10,J10-R10))) -> 0 | T10: =IF(A10="","",IF(N10="Completed","Green",IF(AND(J10<>"",TODAY()>J10),"Red",IF(AND(J10<>"",TODAY()+3>=J10),"Amber","Green")))) -> Green | V10: =IF(AND(OR($P10="☑",$P10=TRUE,$P10=1,$P10="Y",$P10="Yes",$P10="✔",$P10="☒",$P10="X"),$D10<>""),COUNTIF($P$2:$P10,"☑")+COUNTIF($P$2:$P10,TRUE)+COUNTIF($P$2:$P10,1)+COUNTIF($P$2:$P10,"Y")+COUNTIF($P$2:$P10,"Yes")+COUNTIF($P$2:$P10,"✔")+COUNTIF($P$2:$P10,"☒")+COUNTIF($P$2:$P10,"X"),"") -> 9
A11: =IF(D11="","","T-"&TEXT(ROW()-1,"000")) -> T-010 | B11: 2.3 | C11: Execution | D11: EOB Processing | E11: Development | F11: T-010 | G11: Himansu Sekhar Bandha | H11: Zapcom Team | I11: 45819 | J11: 45888 | K11: =IF(OR(I11="",J11=""),"",J11-I11+1) -> 70 | L11: 45819 | M11: 45888 | N11: Completed | O11: 1 | P11: TRUE | Q11: 45819 | R11: 45888 | S11: =IF(A11="","",IF(OR(R11="",J11=""),"",IF(M11<>"",M11-R11,J11-R11))) -> 0 | T11: =IF(A11="","",IF(N11="Completed","Green",IF(AND(J11<>"",TODAY()>J11),"Red",IF(AND(J11<>"",TODAY()+3>=J11),"Amber","Green")))) -> Green | V11: =IF(AND(OR($P11="☑",$P11=TRUE,$P11=1,$P11="Y",$P11="Yes",$P11="✔",$P11="☒",$P11="X"),$D11<>""),COUNTIF($P$2:$P11,"☑")+COUNTIF($P$2:$P11,TRUE)+COUNTIF($P$2:$P11,1)+COUNTIF($P$2:$P11,"Y")+COUNTIF($P$2:$P11,"Yes")+COUNTIF($P$2:$P11,"✔")+COUNTIF($P$2:$P11,"☒")+COUNTIF($P$2:$P11,"X"),"") -> 10
A12: =IF(D12="","","T-"&TEXT(ROW()-1,"000")) -> T-011 | B12: 2.4 | C12: Execution | D12: Implement HIPAA-compliant processes | E12: Development | F12: T-010 | G12: Himansu Sekhar Bandha | H12: Zapcom Team | I12: 45833 | J12: 45860 | K12: =IF(OR(I12="",J12=""),"",J12-I12+1) -> 28 | L12: 46027 | M12: 46112 | N12: Completed | O12: 1 | P12: TRUE | Q12: 46027 | R12: 46112 | S12: =IF(A12="","",IF(OR(R12="",J12=""),"",IF(M12<>"",M12-R12,J12-R12))) -> 0 | T12: =IF(A12="","",IF(N12="Completed","Green",IF(AND(J12<>"",TODAY()>J12),"Red",IF(AND(J12<>"",TODAY()+3>=J12),"Amber","Green")))) -> Green | V12: =IF(AND(OR($P12="☑",$P12=TRUE,$P12=1,$P12="Y",$P12="Yes",$P12="✔",$P12="☒",$P12="X"),$D12<>""),COUNTIF($P$2:$P12,"☑")+COUNTIF($P$2:$P12,TRUE)+COUNTIF($P$2:$P12,1)+COUNTIF($P$2:$P12,"Y")+COUNTIF($P$2:$P12,"Yes")+COUNTIF($P$2:$P12,"✔")+COUNTIF($P$2:$P12,"☒")+COUNTIF($P$2:$P12,"X"),"") -> 11
A13: =IF(D13="","","T-"&TEXT(ROW()-1,"000")) -> T-012 | B13: 2.5 | C13: Execution | D13: OpenDental API Integration | E13: Development | F13: T-010 | G13: Himansu Sekhar Bandha | H13: Zapcom Team | I13: 45819 | J13: 45860 | K13: =IF(OR(I13="",J13=""),"",J13-I13+1) -> 42 | L13: 46034 | M13: 46112 | N13: Completed | O13: 1 | P13: TRUE | Q13: 46034 | R13: 46112 | S13: =IF(A13="","",IF(OR(R13="",J13=""),"",IF(M13<>"",M13-R13,J13-R13))) -> 0 | T13: =IF(A13="","",IF(N13="Completed","Green",IF(AND(J13<>"",TODAY()>J13),"Red",IF(AND(J13<>"",TODAY()+3>=J13),"Amber","Green")))) -> Green | V13: =IF(AND(OR($P13="☑",$P13=TRUE,$P13=1,$P13="Y",$P13="Yes",$P13="✔",$P13="☒",$P13="X"),$D13<>""),COUNTIF($P$2:$P13,"☑")+COUNTIF($P$2:$P13,TRUE)+COUNTIF($P$2:$P13,1)+COUNTIF($P$2:$P13,"Y")+COUNTIF($P$2:$P13,"Yes")+COUNTIF($P$2:$P13,"✔")+COUNTIF($P$2:$P13,"☒")+COUNTIF($P$2:$P13,"X"),"") -> 12
A14: =IF(D14="","","T-"&TEXT(ROW()-1,"000")) -> T-013 | B14: 2.6 | C14: Execution | D14: Performance Optimization | E14: Development | F14: T-011,T-012,T-013,T-014,T-015,T-016 | G14: Himansu Sekhar Bandha | H14: Zapcom Team | I14: 45847 | J14: 45888 | K14: =IF(OR(I14="",J14=""),"",J14-I14+1) -> 42 | L14: 46027 | M14: 46112 | N14: Completed | O14: 1 | P14: TRUE | Q14: 46027 | R14: 46112 | S14: =IF(A14="","",IF(OR(R14="",J14=""),"",IF(M14<>"",M14-R14,J14-R14))) -> 0 | T14: =IF(A14="","",IF(N14="Completed","Green",IF(AND(J14<>"",TODAY()>J14),"Red",IF(AND(J14<>"",TODAY()+3>=J14),"Amber","Green")))) -> Green | V14: =IF(AND(OR($P14="☑",$P14=TRUE,$P14=1,$P14="Y",$P14="Yes",$P14="✔",$P14="☒",$P14="X"),$D14<>""),COUNTIF($P$2:$P14,"☑")+COUNTIF($P$2:$P14,TRUE)+COUNTIF($P$2:$P14,1)+COUNTIF($P$2:$P14,"Y")+COUNTIF($P$2:$P14,"Yes")+COUNTIF($P$2:$P14,"✔")+COUNTIF($P$2:$P14,"☒")+COUNTIF($P$2:$P14,"X"),"") -> 13
... A24: =IF(D24="","","T-"&TEXT(ROW()-1,"000")) -> T-023 | B24: 3.1 | C24: Closure | D24: Closure documentation | E24: Jira / Resolution Tracting | F24: T-021,T-022 | G24: Suseela Nookala | H24: PMO / Zapcom | I24: 46143 | J24: 46143 | K24: =IF(OR(I24="",J24=""),"",J24-I24+1) -> 1 | L24: 46143 | M24: 46143 | N24: In Progress | O24: 1 | P24: TRUE | Q24: 46143 | R24: 46143 | S24: =IF(A24="","",IF(OR(R24="",J24=""),"",IF(M24<>"",M24-R24,J24-R24))) -> 0 | T24: =IF(A24="","",IF(N24="Completed","Green",IF(AND(J24<>"",TODAY()>J24),"Red",IF(AND(J24<>"",TODAY()+3>=J24),"Amber","Green")))) -> Red | V24: =IF(AND(OR($P24="☑",$P24=TRUE,$P24=1,$P24="Y",$P24="Yes",$P24="✔",$P24="☒",$P24="X"),$D24<>""),COUNTIF($P$2:$P24,"☑")+COUNTIF($P$2:$P24,TRUE)+COUNTIF($P$2:$P24,1)+COUNTIF($P$2:$P24,"Y")+COUNTIF($P$2:$P24,"Yes")+COUNTIF($P$2:$P24,"✔")+COUNTIF($P$2:$P24,"☒")+COUNTIF($P$2:$P24,"X"),"") -> 23
A25: =IF(D25="","","T-"&TEXT(ROW()-1,"000")) | B25: 3.2 | C25: Monitoring & Control | P25: FALSE | V25: =IF(AND(OR($P25="☑",$P25=TRUE,$P25=1,$P25="Y",$P25="Yes",$P25="✔",$P25="☒",$P25="X"),$D25<>""),COUNTIF($P$2:$P25,"☑")+COUNTIF($P$2:$P25,TRUE)+COUNTIF($P$2:$P25,1)+COUNTIF($P$2:$P25,"Y")+COUNTIF($P$2:$P25,"Yes")+COUNTIF($P$2:$P25,"✔")+COUNTIF($P$2:$P25,"☒")+COUNTIF($P$2:$P25,"X"),"")
A26: =IF(D26="","","T-"&TEXT(ROW()-1,"000")) | B26: 3.3 | C26: Monitoring & Control | P26: FALSE | V26: =IF(AND(OR($P26="☑",$P26=TRUE,$P26=1,$P26="Y",$P26="Yes",$P26="✔",$P26="☒",$P26="X"),$D26<>""),COUNTIF($P$2:$P26,"☑")+COUNTIF($P$2:$P26,TRUE)+COUNTIF($P$2:$P26,1)+COUNTIF($P$2:$P26,"Y")+COUNTIF($P$2:$P26,"Yes")+COUNTIF($P$2:$P26,"✔")+COUNTIF($P$2:$P26,"☒")+COUNTIF($P$2:$P26,"X"),"")
A27: =IF(D27="","","T-"&TEXT(ROW()-1,"000")) | B27: 4 | C27: Monitoring & Control | P27: FALSE | V27: =IF(AND(OR($P27="☑",$P27=TRUE,$P27=1,$P27="Y",$P27="Yes",$P27="✔",$P27="☒",$P27="X"),$D27<>""),COUNTIF($P$2:$P27,"☑")+COUNTIF($P$2:$P27,TRUE)+COUNTIF($P$2:$P27,1)+COUNTIF($P$2:$P27,"Y")+COUNTIF($P$2:$P27,"Yes")+COUNTIF($P$2:$P27,"✔")+COUNTIF($P$2:$P27,"☒")+COUNTIF($P$2:$P27,"X"),"")
A28: =IF(D28="","","T-"&TEXT(ROW()-1,"000")) | B28: 4.1 | C28: Monitoring & Control | P28: FALSE | V28: =IF(AND(OR($P28="☑",$P28=TRUE,$P28=1,$P28="Y",$P28="Yes",$P28="✔",$P28="☒",$P28="X"),$D28<>""),COUNTIF($P$2:$P28,"☑")+COUNTIF($P$2:$P28,TRUE)+COUNTIF($P$2:$P28,1)+COUNTIF($P$2:$P28,"Y")+COUNTIF($P$2:$P28,"Yes")+COUNTIF($P$2:$P28,"✔")+COUNTIF($P$2:$P28,"☒")+COUNTIF($P$2:$P28,"X"),"")
A29: =IF(D29="","","T-"&TEXT(ROW()-1,"000")) | B29: 4.2 | C29: Monitoring & Control | P29: FALSE | V29: =IF(AND(OR($P29="☑",$P29=TRUE,$P29=1,$P29="Y",$P29="Yes",$P29="✔",$P29="☒",$P29="X"),$D29<>""),COUNTIF($P$2:$P29,"☑")+COUNTIF($P$2:$P29,TRUE)+COUNTIF($P$2:$P29,1)+COUNTIF($P$2:$P29,"Y")+COUNTIF($P$2:$P29,"Yes")+COUNTIF($P$2:$P29,"✔")+COUNTIF($P$2:$P29,"☒")+COUNTIF($P$2:$P29,"X"),"")
A30: =IF(D30="","","T-"&TEXT(ROW()-1,"000")) | B30: 4.3 | C30: Closure | P30: FALSE | V30: =IF(AND(OR($P30="☑",$P30=TRUE,$P30=1,$P30="Y",$P30="Yes",$P30="✔",$P30="☒",$P30="X"),$D30<>""),COUNTIF($P$2:$P30,"☑")+COUNTIF($P$2:$P30,TRUE)+COUNTIF($P$2:$P30,1)+COUNTIF($P$2:$P30,"Y")+COUNTIF($P$2:$P30,"Yes")+COUNTIF($P$2:$P30,"✔")+COUNTIF($P$2:$P30,"☒")+COUNTIF($P$2:$P30,"X"),"")
A31: =IF(D31="","","T-"&TEXT(ROW()-1,"000")) | B31: 5 | C31: Initiation | P31: FALSE | V31: =IF(AND(OR($P31="☑",$P31=TRUE,$P31=1,$P31="Y",$P31="Yes",$P31="✔",$P31="☒",$P31="X"),$D31<>""),COUNTIF($P$2:$P31,"☑")+COUNTIF($P$2:$P31,TRUE)+COUNTIF($P$2:$P31,1)+COUNTIF($P$2:$P31,"Y")+COUNTIF($P$2:$P31,"Yes")+COUNTIF($P$2:$P31,"✔")+COUNTIF($P$2:$P31,"☒")+COUNTIF($P$2:$P31,"X"),"")
A32: =IF(D32="","","T-"&TEXT(ROW()-1,"000")) | B32: 5.1 | C32: Initiation | P32: FALSE | V32: =IF(AND(OR($P32="☑",$P32=TRUE,$P32=1,$P32="Y",$P32="Yes",$P32="✔",$P32="☒",$P32="X"),$D32<>""),COUNTIF($P$2:$P32,"☑")+COUNTIF($P$2:$P32,TRUE)+COUNTIF($P$2:$P32,1)+COUNTIF($P$2:$P32,"Y")+COUNTIF($P$2:$P32,"Yes")+COUNTIF($P$2:$P32,"✔")+COUNTIF($P$2:$P32,"☒")+COUNTIF($P$2:$P32,"X"),"")
A33: =IF(D33="","","T-"&TEXT(ROW()-1,"000")) | B33: 5.2 | C33: Initiation | P33: FALSE | V33: =IF(AND(OR($P33="☑",$P33=TRUE,$P33=1,$P33="Y",$P33="Yes",$P33="✔",$P33="☒",$P33="X"),$D33<>""),COUNTIF($P$2:$P33,"☑")+COUNTIF($P$2:$P33,TRUE)+COUNTIF($P$2:$P33,1)+COUNTIF($P$2:$P33,"Y")+COUNTIF($P$2:$P33,"Yes")+COUNTIF($P$2:$P33,"✔")+COUNTIF($P$2:$P33,"☒")+COUNTIF($P$2:$P33,"X"),"")
A34: =IF(D34="","","T-"&TEXT(ROW()-1,"000")) | B34: 5.3 | C34: Execution | P34: FALSE | V34: =IF(AND(OR($P34="☑",$P34=TRUE,$P34=1,$P34="Y",$P34="Yes",$P34="✔",$P34="☒",$P34="X"),$D34<>""),COUNTIF($P$2:$P34,"☑")+COUNTIF($P$2:$P34,TRUE)+COUNTIF($P$2:$P34,1)+COUNTIF($P$2:$P34,"Y")+COUNTIF($P$2:$P34,"Yes")+COUNTIF($P$2:$P34,"✔")+COUNTIF($P$2:$P34,"☒")+COUNTIF($P$2:$P34,"X"),"")
A35: =IF(D35="","","T-"&TEXT(ROW()-1,"000")) | B35: 5.4 | C35: Execution | P35: FALSE | V35: =IF(AND(OR($P35="☑",$P35=TRUE,$P35=1,$P35="Y",$P35="Yes",$P35="✔",$P35="☒",$P35="X"),$D35<>""),COUNTIF($P$2:$P35,"☑")+COUNTIF($P$2:$P35,TRUE)+COUNTIF($P$2:$P35,1)+COUNTIF($P$2:$P35,"Y")+COUNTIF($P$2:$P35,"Yes")+COUNTIF($P$2:$P35,"✔")+COUNTIF($P$2:$P35,"☒")+COUNTIF($P$2:$P35,"X"),"")
A36: =IF(D36="","","T-"&TEXT(ROW()-1,"000")) | B36: 5.5 | C36: Execution | P36: FALSE | V36: =IF(AND(OR($P36="☑",$P36=TRUE,$P36=1,$P36="Y",$P36="Yes",$P36="✔",$P36="☒",$P36="X"),$D36<>""),COUNTIF($P$2:$P36,"☑")+COUNTIF($P$2:$P36,TRUE)+COUNTIF($P$2:$P36,1)+COUNTIF($P$2:$P36,"Y")+COUNTIF($P$2:$P36,"Yes")+COUNTIF($P$2:$P36,"✔")+COUNTIF($P$2:$P36,"☒")+COUNTIF($P$2:$P36,"X"),"")
... A51: =IF(D51="","","T-"&TEXT(ROW()-1,"000")) | B51: 7.1 | C51: Planning | P51: FALSE | V51: =IF(AND(OR($P51="☑",$P51=TRUE,$P51=1,$P51="Y",$P51="Yes",$P51="✔",$P51="☒",$P51="X"),$D51<>""),COUNTIF($P$2:$P51,"☑")+COUNTIF($P$2:$P51,TRUE)+COUNTIF($P$2:$P51,1)+COUNTIF($P$2:$P51,"Y")+COUNTIF($P$2:$P51,"Yes")+COUNTIF($P$2:$P51,"✔")+COUNTIF($P$2:$P51,"☒")+COUNTIF($P$2:$P51,"X"),"")
A52: =IF(D52="","","T-"&TEXT(ROW()-1,"000")) | K52: =IF(OR(I52="",J52=""),"",J52-I52+1) | P52: FALSE | S52: =IF(A52="","",IF(OR(R52="",J52=""),"",IF(M52<>"",M52-R52,J52-R52))) | T52: =IF(A52="","",IF(N52="Completed","Green",IF(AND(J52<>"",TODAY()>J52),"Red",IF(AND(J52<>"",TODAY()+3>=J52),"Amber","Green")))) | V52: =IF(AND(OR($P52="☑",$P52=TRUE,$P52=1,$P52="Y",$P52="Yes",$P52="✔",$P52="☒",$P52="X"),$D52<>""),COUNTIF($P$2:$P52,"☑")+COUNTIF($P$2:$P52,TRUE)+COUNTIF($P$2:$P52,1)+COUNTIF($P$2:$P52,"Y")+COUNTIF($P$2:$P52,"Yes")+COUNTIF($P$2:$P52,"✔")+COUNTIF($P$2:$P52,"☒")+COUNTIF($P$2:$P52,"X"),"")
A53: =IF(D53="","","T-"&TEXT(ROW()-1,"000")) | K53: =IF(OR(I53="",J53=""),"",J53-I53+1) | P53: FALSE | S53: =IF(A53="","",IF(OR(R53="",J53=""),"",IF(M53<>"",M53-R53,J53-R53))) | T53: =IF(A53="","",IF(N53="Completed","Green",IF(AND(J53<>"",TODAY()>J53),"Red",IF(AND(J53<>"",TODAY()+3>=J53),"Amber","Green")))) | V53: =IF(AND(OR($P53="☑",$P53=TRUE,$P53=1,$P53="Y",$P53="Yes",$P53="✔",$P53="☒",$P53="X"),$D53<>""),COUNTIF($P$2:$P53,"☑")+COUNTIF($P$2:$P53,TRUE)+COUNTIF($P$2:$P53,1)+COUNTIF($P$2:$P53,"Y")+COUNTIF($P$2:$P53,"Yes")+COUNTIF($P$2:$P53,"✔")+COUNTIF($P$2:$P53,"☒")+COUNTIF($P$2:$P53,"X"),"")
A54: =IF(D54="","","T-"&TEXT(ROW()-1,"000")) | K54: =IF(OR(I54="",J54=""),"",J54-I54+1) | P54: FALSE | S54: =IF(A54="","",IF(OR(R54="",J54=""),"",IF(M54<>"",M54-R54,J54-R54))) | T54: =IF(A54="","",IF(N54="Completed","Green",IF(AND(J54<>"",TODAY()>J54),"Red",IF(AND(J54<>"",TODAY()+3>=J54),"Amber","Green")))) | V54: =IF(AND(OR($P54="☑",$P54=TRUE,$P54=1,$P54="Y",$P54="Yes",$P54="✔",$P54="☒",$P54="X"),$D54<>""),COUNTIF($P$2:$P54,"☑")+COUNTIF($P$2:$P54,TRUE)+COUNTIF($P$2:$P54,1)+COUNTIF($P$2:$P54,"Y")+COUNTIF($P$2:$P54,"Yes")+COUNTIF($P$2:$P54,"✔")+COUNTIF($P$2:$P54,"☒")+COUNTIF($P$2:$P54,"X"),"")
A55: =IF(D55="","","T-"&TEXT(ROW()-1,"000")) | K55: =IF(OR(I55="",J55=""),"",J55-I55+1) | P55: FALSE | S55: =IF(A55="","",IF(OR(R55="",J55=""),"",IF(M55<>"",M55-R55,J55-R55))) | T55: =IF(A55="","",IF(N55="Completed","Green",IF(AND(J55<>"",TODAY()>J55),"Red",IF(AND(J55<>"",TODAY()+3>=J55),"Amber","Green")))) | V55: =IF(AND(OR($P55="☑",$P55=TRUE,$P55=1,$P55="Y",$P55="Yes",$P55="✔",$P55="☒",$P55="X"),$D55<>""),COUNTIF($P$2:$P55,"☑")+COUNTIF($P$2:$P55,TRUE)+COUNTIF($P$2:$P55,1)+COUNTIF($P$2:$P55,"Y")+COUNTIF($P$2:$P55,"Yes")+COUNTIF($P$2:$P55,"✔")+COUNTIF($P$2:$P55,"☒")+COUNTIF($P$2:$P55,"X"),"")
A56: =IF(D56="","","T-"&TEXT(ROW()-1,"000")) | K56: =IF(OR(I56="",J56=""),"",J56-I56+1) | P56: FALSE | S56: =IF(A56="","",IF(OR(R56="",J56=""),"",IF(M56<>"",M56-R56,J56-R56))) | T56: =IF(A56="","",IF(N56="Completed","Green",IF(AND(J56<>"",TODAY()>J56),"Red",IF(AND(J56<>"",TODAY()+3>=J56),"Amber","Green")))) | V56: =IF(AND(OR($P56="☑",$P56=TRUE,$P56=1,$P56="Y",$P56="Yes",$P56="✔",$P56="☒",$P56="X"),$D56<>""),COUNTIF($P$2:$P56,"☑")+COUNTIF($P$2:$P56,TRUE)+COUNTIF($P$2:$P56,1)+COUNTIF($P$2:$P56,"Y")+COUNTIF($P$2:$P56,"Yes")+COUNTIF($P$2:$P56,"✔")+COUNTIF($P$2:$P56,"☒")+COUNTIF($P$2:$P56,"X"),"")
A57: =IF(D57="","","T-"&TEXT(ROW()-1,"000")) | K57: =IF(OR(I57="",J57=""),"",J57-I57+1) | P57: FALSE | S57: =IF(A57="","",IF(OR(R57="",J57=""),"",IF(M57<>"",M57-R57,J57-R57))) | T57: =IF(A57="","",IF(N57="Completed","Green",IF(AND(J57<>"",TODAY()>J57),"Red",IF(AND(J57<>"",TODAY()+3>=J57),"Amber","Green")))) | V57: =IF(AND(OR($P57="☑",$P57=TRUE,$P57=1,$P57="Y",$P57="Yes",$P57="✔",$P57="☒",$P57="X"),$D57<>""),COUNTIF($P$2:$P57,"☑")+COUNTIF($P$2:$P57,TRUE)+COUNTIF($P$2:$P57,1)+COUNTIF($P$2:$P57,"Y")+COUNTIF($P$2:$P57,"Yes")+COUNTIF($P$2:$P57,"✔")+COUNTIF($P$2:$P57,"☒")+COUNTIF($P$2:$P57,"X"),"")
A58: =IF(D58="","","T-"&TEXT(ROW()-1,"000")) | K58: =IF(OR(I58="",J58=""),"",J58-I58+1) | P58: FALSE | S58: =IF(A58="","",IF(OR(R58="",J58=""),"",IF(M58<>"",M58-R58,J58-R58))) | T58: =IF(A58="","",IF(N58="Completed","Green",IF(AND(J58<>"",TODAY()>J58),"Red",IF(AND(J58<>"",TODAY()+3>=J58),"Amber","Green")))) | V58: =IF(AND(OR($P58="☑",$P58=TRUE,$P58=1,$P58="Y",$P58="Yes",$P58="✔",$P58="☒",$P58="X"),$D58<>""),COUNTIF($P$2:$P58,"☑")+COUNTIF($P$2:$P58,TRUE)+COUNTIF($P$2:$P58,1)+COUNTIF($P$2:$P58,"Y")+COUNTIF($P$2:$P58,"Yes")+COUNTIF($P$2:$P58,"✔")+COUNTIF($P$2:$P58,"☒")+COUNTIF($P$2:$P58,"X"),"")
A59: =IF(D59="","","T-"&TEXT(ROW()-1,"000")) | K59: =IF(OR(I59="",J59=""),"",J59-I59+1) | P59: FALSE | S59: =IF(A59="","",IF(OR(R59="",J59=""),"",IF(M59<>"",M59-R59,J59-R59))) | T59: =IF(A59="","",IF(N59="Completed","Green",IF(AND(J59<>"",TODAY()>J59),"Red",IF(AND(J59<>"",TODAY()+3>=J59),"Amber","Green")))) | V59: =IF(AND(OR($P59="☑",$P59=TRUE,$P59=1,$P59="Y",$P59="Yes",$P59="✔",$P59="☒",$P59="X"),$D59<>""),COUNTIF($P$2:$P59,"☑")+COUNTIF($P$2:$P59,TRUE)+COUNTIF($P$2:$P59,1)+COUNTIF($P$2:$P59,"Y")+COUNTIF($P$2:$P59,"Yes")+COUNTIF($P$2:$P59,"✔")+COUNTIF($P$2:$P59,"☒")+COUNTIF($P$2:$P59,"X"),"")
A60: =IF(D60="","","T-"&TEXT(ROW()-1,"000")) | K60: =IF(OR(I60="",J60=""),"",J60-I60+1) | P60: FALSE | S60: =IF(A60="","",IF(OR(R60="",J60=""),"",IF(M60<>"",M60-R60,J60-R60))) | T60: =IF(A60="","",IF(N60="Completed","Green",IF(AND(J60<>"",TODAY()>J60),"Red",IF(AND(J60<>"",TODAY()+3>=J60),"Amber","Green")))) | V60: =IF(AND(OR($P60="☑",$P60=TRUE,$P60=1,$P60="Y",$P60="Yes",$P60="✔",$P60="☒",$P60="X"),$D60<>""),COUNTIF($P$2:$P60,"☑")+COUNTIF($P$2:$P60,TRUE)+COUNTIF($P$2:$P60,1)+COUNTIF($P$2:$P60,"Y")+COUNTIF($P$2:$P60,"Yes")+COUNTIF($P$2:$P60,"✔")+COUNTIF($P$2:$P60,"☒")+COUNTIF($P$2:$P60,"X"),"")
A61: =IF(D61="","","T-"&TEXT(ROW()-1,"000")) | K61: =IF(OR(I61="",J61=""),"",J61-I61+1) | P61: FALSE | S61: =IF(A61="","",IF(OR(R61="",J61=""),"",IF(M61<>"",M61-R61,J61-R61))) | T61: =IF(A61="","",IF(N61="Completed","Green",IF(AND(J61<>"",TODAY()>J61),"Red",IF(AND(J61<>"",TODAY()+3>=J61),"Amber","Green")))) | V61: =IF(AND(OR($P61="☑",$P61=TRUE,$P61=1,$P61="Y",$P61="Yes",$P61="✔",$P61="☒",$P61="X"),$D61<>""),COUNTIF($P$2:$P61,"☑")+COUNTIF($P$2:$P61,TRUE)+COUNTIF($P$2:$P61,1)+COUNTIF($P$2:$P61,"Y")+COUNTIF($P$2:$P61,"Yes")+COUNTIF($P$2:$P61,"✔")+COUNTIF($P$2:$P61,"☒")+COUNTIF($P$2:$P61,"X"),"")
A62: =IF(D62="","","T-"&TEXT(ROW()-1,"000")) | K62: =IF(OR(I62="",J62=""),"",J62-I62+1) | P62: FALSE | S62: =IF(A62="","",IF(OR(R62="",J62=""),"",IF(M62<>"",M62-R62,J62-R62))) | T62: =IF(A62="","",IF(N62="Completed","Green",IF(AND(J62<>"",TODAY()>J62),"Red",IF(AND(J62<>"",TODAY()+3>=J62),"Amber","Green")))) | V62: =IF(AND(OR($P62="☑",$P62=TRUE,$P62=1,$P62="Y",$P62="Yes",$P62="✔",$P62="☒",$P62="X"),$D62<>""),COUNTIF($P$2:$P62,"☑")+COUNTIF($P$2:$P62,TRUE)+COUNTIF($P$2:$P62,1)+COUNTIF($P$2:$P62,"Y")+COUNTIF($P$2:$P62,"Yes")+COUNTIF($P$2:$P62,"✔")+COUNTIF($P$2:$P62,"☒")+COUNTIF($P$2:$P62,"X"),"")
A63: =IF(D63="","","T-"&TEXT(ROW()-1,"000")) | K63: =IF(OR(I63="",J63=""),"",J63-I63+1) | P63: FALSE | S63: =IF(A63="","",IF(OR(R63="",J63=""),"",IF(M63<>"",M63-R63,J63-R63))) | T63: =IF(A63="","",IF(N63="Completed","Green",IF(AND(J63<>"",TODAY()>J63),"Red",IF(AND(J63<>"",TODAY()+3>=J63),"Amber","Green")))) | V63: =IF(AND(OR($P63="☑",$P63=TRUE,$P63=1,$P63="Y",$P63="Yes",$P63="✔",$P63="☒",$P63="X"),$D63<>""),COUNTIF($P$2:$P63,"☑")+COUNTIF($P$2:$P63,TRUE)+COUNTIF($P$2:$P63,1)+COUNTIF($P$2:$P63,"Y")+COUNTIF($P$2:$P63,"Yes")+COUNTIF($P$2:$P63,"✔")+COUNTIF($P$2:$P63,"☒")+COUNTIF($P$2:$P63,"X"),"")
...

Sheet Milestone Tracker
A1: Milestone Ref | B1: WBS | C1: Phase | D1: Milestone / Task Name | E1: Owner | F1: Planned Start Date | G1: Planned End Date | H1: Actual End Date | I1: Status | J1: % Complete | K1: Baseline End Date | L1: Variance (Days) | M1: RAG Status | N1: Notes | O1: _MilestoneSeq
A2: =IF($O2="","",INDEX('Project Plan'!$A$2:$A$201,MATCH($O2,'Project Plan'!$V$2:$V$201,0))) -> T-001 | B2: =IF($O2="","",INDEX('Project Plan'!$B$2:$B$201,MATCH($O2,'Project Plan'!$V$2:$V$201,0))) -> 1 | C2: =IF($O2="","",INDEX('Project Plan'!$C$2:$C$201,MATCH($O2,'Project Plan'!$V$2:$V$201,0))) -> Initiation | D2: =IF($O2="","",INDEX('Project Plan'!$D$2:$D$201,MATCH($O2,'Project Plan'!$V$2:$V$201,0))) -> Project Kickoff & Mobilization | E2: =IF($O2="","",INDEX('Project Plan'!$G$2:$G$201,MATCH($O2,'Project Plan'!$V$2:$V$201,0))) -> Suseela Nookala | F2: =IF($O2="","",INDEX('Project Plan'!$I$2:$I$201,MATCH($O2,'Project Plan'!$V$2:$V$201,0))) -> 45663 | G2: =IF($O2="","",INDEX('Project Plan'!$J$2:$J$201,MATCH($O2,'Project Plan'!$V$2:$V$201,0))) -> 45663 | H2: =IF($O2="","",INDEX('Project Plan'!$M$2:$M$201,MATCH($O2,'Project Plan'!$V$2:$V$201,0))) -> 45663 | I2: =IF($O2="","",INDEX('Project Plan'!$N$2:$N$201,MATCH($O2,'Project Plan'!$V$2:$V$201,0))) -> Completed | J2: =IF($O2="","",INDEX('Project Plan'!$O$2:$O$201,MATCH($O2,'Project Plan'!$V$2:$V$201,0))) -> 1 | K2: =IF($O2="","",INDEX('Project Plan'!$R$2:$R$201,MATCH($O2,'Project Plan'!$V$2:$V$201,0))) -> 45663 | L2: =IF($O2="","",INDEX('Project Plan'!$S$2:$S$201,MATCH($O2,'Project Plan'!$V$2:$V$201,0))) -> 0 | M2: =IF($O2="","",INDEX('Project Plan'!$T$2:$T$201,MATCH($O2,'Project Plan'!$V$2:$V$201,0))) -> Green | N2: =IF($O2="","",INDEX('Project Plan'!$U$2:$U$201,MATCH($O2,'Project Plan'!$V$2:$V$201,0))) -> 0 | O2: =IF(ROW()-1<=MAX('Project Plan'!$V$2:$V$201),ROW()-1,"") -> 1
A3: =IF($O3="","",INDEX('Project Plan'!$A$2:$A$201,MATCH($O3,'Project Plan'!$V$2:$V$201,0))) -> T-002 | B3: =IF($O3="","",INDEX('Project Plan'!$B$2:$B$201,MATCH($O3,'Project Plan'!$V$2:$V$201,0))) -> 1.1 | C3: =IF($O3="","",INDEX('Project Plan'!$C$2:$C$201,MATCH($O3,'Project Plan'!$V$2:$V$201,0))) -> Initiation | D3: =IF($O3="","",INDEX('Project Plan'!$D$2:$D$201,MATCH($O3,'Project Plan'!$V$2:$V$201,0))) -> SOW Commencement | E3: =IF($O3="","",INDEX('Project Plan'!$G$2:$G$201,MATCH($O3,'Project Plan'!$V$2:$V$201,0))) -> Deepak Puranam/Sai Konda | F3: =IF($O3="","",INDEX('Project Plan'!$I$2:$I$201,MATCH($O3,'Project Plan'!$V$2:$V$201,0))) -> 45663 | G3: =IF($O3="","",INDEX('Project Plan'!$J$2:$J$201,MATCH($O3,'Project Plan'!$V$2:$V$201,0))) -> 45814 | H3: =IF($O3="","",INDEX('Project Plan'!$M$2:$M$201,MATCH($O3,'Project Plan'!$V$2:$V$201,0))) -> 45814 | I3: =IF($O3="","",INDEX('Project Plan'!$N$2:$N$201,MATCH($O3,'Project Plan'!$V$2:$V$201,0))) -> Completed | J3: =IF($O3="","",INDEX('Project Plan'!$O$2:$O$201,MATCH($O3,'Project Plan'!$V$2:$V$201,0))) -> 1 | K3: =IF($O3="","",INDEX('Project Plan'!$R$2:$R$201,MATCH($O3,'Project Plan'!$V$2:$V$201,0))) -> 45814 | L3: =IF($O3="","",INDEX('Project Plan'!$S$2:$S$201,MATCH($O3,'Project Plan'!$V$2:$V$201,0))) -> 0 | M3: =IF($O3="","",INDEX('Project Plan'!$T$2:$T$201,MATCH($O3,'Project Plan'!$V$2:$V$201,0))) -> Green | N3: =IF($O3="","",INDEX('Project Plan'!$U$2:$U$201,MATCH($O3,'Project Plan'!$V$2:$V$201,0))) -> 0 | O3: =IF(ROW()-1<=MAX('Project Plan'!$V$2:$V$201),ROW()-1,"") -> 2
A4: =IF($O4="","",INDEX('Project Plan'!$A$2:$A$201,MATCH($O4,'Project Plan'!$V$2:$V$201,0))) -> T-003 | B4: =IF($O4="","",INDEX('Project Plan'!$B$2:$B$201,MATCH($O4,'Project Plan'!$V$2:$V$201,0))) -> 1.2 | C4: =IF($O4="","",INDEX('Project Plan'!$C$2:$C$201,MATCH($O4,'Project Plan'!$V$2:$V$201,0))) -> Planning | D4: =IF($O4="","",INDEX('Project Plan'!$D$2:$D$201,MATCH($O4,'Project Plan'!$V$2:$V$201,0))) -> Planning | E4: =IF($O4="","",INDEX('Project Plan'!$G$2:$G$201,MATCH($O4,'Project Plan'!$V$2:$V$201,0))) -> Suseela Nookala | F4: =IF($O4="","",INDEX('Project Plan'!$I$2:$I$201,MATCH($O4,'Project Plan'!$V$2:$V$201,0))) -> 45997 | G4: =IF($O4="","",INDEX('Project Plan'!$J$2:$J$201,MATCH($O4,'Project Plan'!$V$2:$V$201,0))) -> 45786 | H4: =IF($O4="","",INDEX('Project Plan'!$M$2:$M$201,MATCH($O4,'Project Plan'!$V$2:$V$201,0))) -> 45786 | I4: =IF($O4="","",INDEX('Project Plan'!$N$2:$N$201,MATCH($O4,'Project Plan'!$V$2:$V$201,0))) -> Completed | J4: =IF($O4="","",INDEX('Project Plan'!$O$2:$O$201,MATCH($O4,'Project Plan'!$V$2:$V$201,0))) -> 1 | K4: =IF($O4="","",INDEX('Project Plan'!$R$2:$R$201,MATCH($O4,'Project Plan'!$V$2:$V$201,0))) -> 45786 | L4: =IF($O4="","",INDEX('Project Plan'!$S$2:$S$201,MATCH($O4,'Project Plan'!$V$2:$V$201,0))) -> 0 | M4: =IF($O4="","",INDEX('Project Plan'!$T$2:$T$201,MATCH($O4,'Project Plan'!$V$2:$V$201,0))) -> Green | N4: =IF($O4="","",INDEX('Project Plan'!$U$2:$U$201,MATCH($O4,'Project Plan'!$V$2:$V$201,0))) -> 0 | O4: =IF(ROW()-1<=MAX('Project Plan'!$V$2:$V$201),ROW()-1,"") -> 3
A5: =IF($O5="","",INDEX('Project Plan'!$A$2:$A$201,MATCH($O5,'Project Plan'!$V$2:$V$201,0))) -> T-004 | B5: =IF($O5="","",INDEX('Project Plan'!$B$2:$B$201,MATCH($O5,'Project Plan'!$V$2:$V$201,0))) -> 1.3 | C5: =IF($O5="","",INDEX('Project Plan'!$C$2:$C$201,MATCH($O5,'Project Plan'!$V$2:$V$201,0))) -> Monitoring & Control | D5: =IF($O5="","",INDEX('Project Plan'!$D$2:$D$201,MATCH($O5,'Project Plan'!$V$2:$V$201,0))) -> Weekly Governance & Stakeholder Reporting | E5: =IF($O5="","",INDEX('Project Plan'!$G$2:$G$201,MATCH($O5,'Project Plan'!$V$2:$V$201,0))) -> Suseela Nookala | F5: =IF($O5="","",INDEX('Project Plan'!$I$2:$I$201,MATCH($O5,'Project Plan'!$V$2:$V$201,0))) -> 45992 | G5: =IF($O5="","",INDEX('Project Plan'!$J$2:$J$201,MATCH($O5,'Project Plan'!$V$2:$V$201,0))) -> 46183 | H5: =IF($O5="","",INDEX('Project Plan'!$M$2:$M$201,MATCH($O5,'Project Plan'!$V$2:$V$201,0))) -> 45838 | I5: =IF($O5="","",INDEX('Project Plan'!$N$2:$N$201,MATCH($O5,'Project Plan'!$V$2:$V$201,0))) -> Completed | J5: =IF($O5="","",INDEX('Project Plan'!$O$2:$O$201,MATCH($O5,'Project Plan'!$V$2:$V$201,0))) -> 1 | K5: =IF($O5="","",INDEX('Project Plan'!$R$2:$R$201,MATCH($O5,'Project Plan'!$V$2:$V$201,0))) -> 45838 | L5: =IF($O5="","",INDEX('Project Plan'!$S$2:$S$201,MATCH($O5,'Project Plan'!$V$2:$V$201,0))) -> 0 | M5: =IF($O5="","",INDEX('Project Plan'!$T$2:$T$201,MATCH($O5,'Project Plan'!$V$2:$V$201,0))) -> Green | N5: =IF($O5="","",INDEX('Project Plan'!$U$2:$U$201,MATCH($O5,'Project Plan'!$V$2:$V$201,0))) -> 0 | O5: =IF(ROW()-1<=MAX('Project Plan'!$V$2:$V$201),ROW()-1,"") -> 4
A6: =IF($O6="","",INDEX('Project Plan'!$A$2:$A$201,MATCH($O6,'Project Plan'!$V$2:$V$201,0))) -> T-005 | B6: =IF($O6="","",INDEX('Project Plan'!$B$2:$B$201,MATCH($O6,'Project Plan'!$V$2:$V$201,0))) -> 1.4 | C6: =IF($O6="","",INDEX('Project Plan'!$C$2:$C$201,MATCH($O6,'Project Plan'!$V$2:$V$201,0))) -> Planning | D6: =IF($O6="","",INDEX('Project Plan'!$D$2:$D$201,MATCH($O6,'Project Plan'!$V$2:$V$201,0))) -> Change Request Scope Realignment & Re-baselining | E6: =IF($O6="","",INDEX('Project Plan'!$G$2:$G$201,MATCH($O6,'Project Plan'!$V$2:$V$201,0))) -> Suseela Nookala | F6: =IF($O6="","",INDEX('Project Plan'!$I$2:$I$201,MATCH($O6,'Project Plan'!$V$2:$V$201,0))) -> 45722 | G6: =IF($O6="","",INDEX('Project Plan'!$J$2:$J$201,MATCH($O6,'Project Plan'!$V$2:$V$201,0))) -> 46129 | H6: =IF($O6="","",INDEX('Project Plan'!$M$2:$M$201,MATCH($O6,'Project Plan'!$V$2:$V$201,0))) -> 45838 | I6: =IF($O6="","",INDEX('Project Plan'!$N$2:$N$201,MATCH($O6,'Project Plan'!$V$2:$V$201,0))) -> Completed | J6: =IF($O6="","",INDEX('Project Plan'!$O$2:$O$201,MATCH($O6,'Project Plan'!$V$2:$V$201,0))) -> 1 | K6: =IF($O6="","",INDEX('Project Plan'!$R$2:$R$201,MATCH($O6,'Project Plan'!$V$2:$V$201,0))) -> 45838 | L6: =IF($O6="","",INDEX('Project Plan'!$S$2:$S$201,MATCH($O6,'Project Plan'!$V$2:$V$201,0))) -> 0 | M6: =IF($O6="","",INDEX('Project Plan'!$T$2:$T$201,MATCH($O6,'Project Plan'!$V$2:$V$201,0))) -> Green | N6: =IF($O6="","",INDEX('Project Plan'!$U$2:$U$201,MATCH($O6,'Project Plan'!$V$2:$V$201,0))) -> 0 | O6: =IF(ROW()-1<=MAX('Project Plan'!$V$2:$V$201),ROW()-1,"") -> 5
A7: =IF($O7="","",INDEX('Project Plan'!$A$2:$A$201,MATCH($O7,'Project Plan'!$V$2:$V$201,0))) -> T-006 | B7: =IF($O7="","",INDEX('Project Plan'!$B$2:$B$201,MATCH($O7,'Project Plan'!$V$2:$V$201,0))) -> 1.5 | C7: =IF($O7="","",INDEX('Project Plan'!$C$2:$C$201,MATCH($O7,'Project Plan'!$V$2:$V$201,0))) -> Planning | D7: =IF($O7="","",INDEX('Project Plan'!$D$2:$D$201,MATCH($O7,'Project Plan'!$V$2:$V$201,0))) -> Change Request Approval / Signature | E7: =IF($O7="","",INDEX('Project Plan'!$G$2:$G$201,MATCH($O7,'Project Plan'!$V$2:$V$201,0))) -> Ibrahim/Sai | F7: =IF($O7="","",INDEX('Project Plan'!$I$2:$I$201,MATCH($O7,'Project Plan'!$V$2:$V$201,0))) -> 45753 | G7: =IF($O7="","",INDEX('Project Plan'!$J$2:$J$201,MATCH($O7,'Project Plan'!$V$2:$V$201,0))) -> 45838 | H7: =IF($O7="","",INDEX('Project Plan'!$M$2:$M$201,MATCH($O7,'Project Plan'!$V$2:$V$201,0))) -> 45838 | I7: =IF($O7="","",INDEX('Project Plan'!$N$2:$N$201,MATCH($O7,'Project Plan'!$V$2:$V$201,0))) -> Completed | J7: =IF($O7="","",INDEX('Project Plan'!$O$2:$O$201,MATCH($O7,'Project Plan'!$V$2:$V$201,0))) -> 1 | K7: =IF($O7="","",INDEX('Project Plan'!$R$2:$R$201,MATCH($O7,'Project Plan'!$V$2:$V$201,0))) -> 45838 | L7: =IF($O7="","",INDEX('Project Plan'!$S$2:$S$201,MATCH($O7,'Project Plan'!$V$2:$V$201,0))) -> 0 | M7: =IF($O7="","",INDEX('Project Plan'!$T$2:$T$201,MATCH($O7,'Project Plan'!$V$2:$V$201,0))) -> Green | N7: =IF($O7="","",INDEX('Project Plan'!$U$2:$U$201,MATCH($O7,'Project Plan'!$V$2:$V$201,0))) -> 0 | O7: =IF(ROW()-1<=MAX('Project Plan'!$V$2:$V$201),ROW()-1,"") -> 6
A8: =IF($O8="","",INDEX('Project Plan'!$A$2:$A$201,MATCH($O8,'Project Plan'!$V$2:$V$201,0))) -> T-007 | B8: =IF($O8="","",INDEX('Project Plan'!$B$2:$B$201,MATCH($O8,'Project Plan'!$V$2:$V$201,0))) -> 2 | C8: =IF($O8="","",INDEX('Project Plan'!$C$2:$C$201,MATCH($O8,'Project Plan'!$V$2:$V$201,0))) -> Execution | D8: =IF($O8="","",INDEX('Project Plan'!$D$2:$D$201,MATCH($O8,'Project Plan'!$V$2:$V$201,0))) -> User Authentication | E8: =IF($O8="","",INDEX('Project Plan'!$G$2:$G$201,MATCH($O8,'Project Plan'!$V$2:$V$201,0))) -> Himansu Sekhar Bandha | F8: =IF($O8="","",INDEX('Project Plan'!$I$2:$I$201,MATCH($O8,'Project Plan'!$V$2:$V$201,0))) -> 45819 | G8: =IF($O8="","",INDEX('Project Plan'!$J$2:$J$201,MATCH($O8,'Project Plan'!$V$2:$V$201,0))) -> 45838 | H8: =IF($O8="","",INDEX('Project Plan'!$M$2:$M$201,MATCH($O8,'Project Plan'!$V$2:$V$201,0))) -> 45838 | I8: =IF($O8="","",INDEX('Project Plan'!$N$2:$N$201,MATCH($O8,'Project Plan'!$V$2:$V$201,0))) -> Completed | J8: =IF($O8="","",INDEX('Project Plan'!$O$2:$O$201,MATCH($O8,'Project Plan'!$V$2:$V$201,0))) -> 1 | K8: =IF($O8="","",INDEX('Project Plan'!$R$2:$R$201,MATCH($O8,'Project Plan'!$V$2:$V$201,0))) -> 45838 | L8: =IF($O8="","",INDEX('Project Plan'!$S$2:$S$201,MATCH($O8,'Project Plan'!$V$2:$V$201,0))) -> 0 | M8: =IF($O8="","",INDEX('Project Plan'!$T$2:$T$201,MATCH($O8,'Project Plan'!$V$2:$V$201,0))) -> Green | N8: =IF($O8="","",INDEX('Project Plan'!$U$2:$U$201,MATCH($O8,'Project Plan'!$V$2:$V$201,0))) -> 0 | O8: =IF(ROW()-1<=MAX('Project Plan'!$V$2:$V$201),ROW()-1,"") -> 7
A9: =IF($O9="","",INDEX('Project Plan'!$A$2:$A$201,MATCH($O9,'Project Plan'!$V$2:$V$201,0))) -> T-008 | B9: =IF($O9="","",INDEX('Project Plan'!$B$2:$B$201,MATCH($O9,'Project Plan'!$V$2:$V$201,0))) -> 2.1 | C9: =IF($O9="","",INDEX('Project Plan'!$C$2:$C$201,MATCH($O9,'Project Plan'!$V$2:$V$201,0))) -> Execution | D9: =IF($O9="","",INDEX('Project Plan'!$D$2:$D$201,MATCH($O9,'Project Plan'!$V$2:$V$201,0))) -> Dashboard (Landing Screen) | E9: =IF($O9="","",INDEX('Project Plan'!$G$2:$G$201,MATCH($O9,'Project Plan'!$V$2:$V$201,0))) -> Himansu Sekhar Bandha | F9: =IF($O9="","",INDEX('Project Plan'!$I$2:$I$201,MATCH($O9,'Project Plan'!$V$2:$V$201,0))) -> 45819 | G9: =IF($O9="","",INDEX('Project Plan'!$J$2:$J$201,MATCH($O9,'Project Plan'!$V$2:$V$201,0))) -> 45838 | H9: =IF($O9="","",INDEX('Project Plan'!$M$2:$M$201,MATCH($O9,'Project Plan'!$V$2:$V$201,0))) -> 45838 | I9: =IF($O9="","",INDEX('Project Plan'!$N$2:$N$201,MATCH($O9,'Project Plan'!$V$2:$V$201,0))) -> Completed | J9: =IF($O9="","",INDEX('Project Plan'!$O$2:$O$201,MATCH($O9,'Project Plan'!$V$2:$V$201,0))) -> 1 | K9: =IF($O9="","",INDEX('Project Plan'!$R$2:$R$201,MATCH($O9,'Project Plan'!$V$2:$V$201,0))) -> 45838 | L9: =IF($O9="","",INDEX('Project Plan'!$S$2:$S$201,MATCH($O9,'Project Plan'!$V$2:$V$201,0))) -> 0 | M9: =IF($O9="","",INDEX('Project Plan'!$T$2:$T$201,MATCH($O9,'Project Plan'!$V$2:$V$201,0))) -> Green | N9: =IF($O9="","",INDEX('Project Plan'!$U$2:$U$201,MATCH($O9,'Project Plan'!$V$2:$V$201,0))) -> 0 | O9: =IF(ROW()-1<=MAX('Project Plan'!$V$2:$V$201),ROW()-1,"") -> 8
A10: =IF($O10="","",INDEX('Project Plan'!$A$2:$A$201,MATCH($O10,'Project Plan'!$V$2:$V$201,0))) -> T-009 | B10: =IF($O10="","",INDEX('Project Plan'!$B$2:$B$201,MATCH($O10,'Project Plan'!$V$2:$V$201,0))) -> 2.1 | C10: =IF($O10="","",INDEX('Project Plan'!$C$2:$C$201,MATCH($O10,'Project Plan'!$V$2:$V$201,0))) -> Execution | D10: =IF($O10="","",INDEX('Project Plan'!$D$2:$D$201,MATCH($O10,'Project Plan'!$V$2:$V$201,0))) -> EOB Upload | E10: =IF($O10="","",INDEX('Project Plan'!$G$2:$G$201,MATCH($O10,'Project Plan'!$V$2:$V$201,0))) -> Himansu Sekhar Bandha | F10: =IF($O10="","",INDEX('Project Plan'!$I$2:$I$201,MATCH($O10,'Project Plan'!$V$2:$V$201,0))) -> 45819 | G10: =IF($O10="","",INDEX('Project Plan'!$J$2:$J$201,MATCH($O10,'Project Plan'!$V$2:$V$201,0))) -> 45846 | H10: =IF($O10="","",INDEX('Project Plan'!$M$2:$M$201,MATCH($O10,'Project Plan'!$V$2:$V$201,0))) -> 45846 | I10: =IF($O10="","",INDEX('Project Plan'!$N$2:$N$201,MATCH($O10,'Project Plan'!$V$2:$V$201,0))) -> Completed | J10: =IF($O10="","",INDEX('Project Plan'!$O$2:$O$201,MATCH($O10,'Project Plan'!$V$2:$V$201,0))) -> 1 | K10: =IF($O10="","",INDEX('Project Plan'!$R$2:$R$201,MATCH($O10,'Project Plan'!$V$2:$V$201,0))) -> 45846 | L10: =IF($O10="","",INDEX('Project Plan'!$S$2:$S$201,MATCH($O10,'Project Plan'!$V$2:$V$201,0))) -> 0 | M10: =IF($O10="","",INDEX('Project Plan'!$T$2:$T$201,MATCH($O10,'Project Plan'!$V$2:$V$201,0))) -> Green | N10: =IF($O10="","",INDEX('Project Plan'!$U$2:$U$201,MATCH($O10,'Project Plan'!$V$2:$V$201,0))) -> 0 | O10: =IF(ROW()-1<=MAX('Project Plan'!$V$2:$V$201),ROW()-1,"") -> 9
A11: =IF($O11="","",INDEX('Project Plan'!$A$2:$A$201,MATCH($O11,'Project Plan'!$V$2:$V$201,0))) -> T-010 | B11: =IF($O11="","",INDEX('Project Plan'!$B$2:$B$201,MATCH($O11,'Project Plan'!$V$2:$V$201,0))) -> 2.3 | C11: =IF($O11="","",INDEX('Project Plan'!$C$2:$C$201,MATCH($O11,'Project Plan'!$V$2:$V$201,0))) -> Execution | D11: =IF($O11="","",INDEX('Project Plan'!$D$2:$D$201,MATCH($O11,'Project Plan'!$V$2:$V$201,0))) -> EOB Processing | E11: =IF($O11="","",INDEX('Project Plan'!$G$2:$G$201,MATCH($O11,'Project Plan'!$V$2:$V$201,0))) -> Himansu Sekhar Bandha | F11: =IF($O11="","",INDEX('Project Plan'!$I$2:$I$201,MATCH($O11,'Project Plan'!$V$2:$V$201,0))) -> 45819 | G11: =IF($O11="","",INDEX('Project Plan'!$J$2:$J$201,MATCH($O11,'Project Plan'!$V$2:$V$201,0))) -> 45888 | H11: =IF($O11="","",INDEX('Project Plan'!$M$2:$M$201,MATCH($O11,'Project Plan'!$V$2:$V$201,0))) -> 45888 | I11: =IF($O11="","",INDEX('Project Plan'!$N$2:$N$201,MATCH($O11,'Project Plan'!$V$2:$V$201,0))) -> Completed | J11: =IF($O11="","",INDEX('Project Plan'!$O$2:$O$201,MATCH($O11,'Project Plan'!$V$2:$V$201,0))) -> 1 | K11: =IF($O11="","",INDEX('Project Plan'!$R$2:$R$201,MATCH($O11,'Project Plan'!$V$2:$V$201,0))) -> 45888 | L11: =IF($O11="","",INDEX('Project Plan'!$S$2:$S$201,MATCH($O11,'Project Plan'!$V$2:$V$201,0))) -> 0 | M11: =IF($O11="","",INDEX('Project Plan'!$T$2:$T$201,MATCH($O11,'Project Plan'!$V$2:$V$201,0))) -> Green | N11: =IF($O11="","",INDEX('Project Plan'!$U$2:$U$201,MATCH($O11,'Project Plan'!$V$2:$V$201,0))) -> 0 | O11: =IF(ROW()-1<=MAX('Project Plan'!$V$2:$V$201),ROW()-1,"") -> 10
A12: =IF($O12="","",INDEX('Project Plan'!$A$2:$A$201,MATCH($O12,'Project Plan'!$V$2:$V$201,0))) -> T-011 | B12: =IF($O12="","",INDEX('Project Plan'!$B$2:$B$201,MATCH($O12,'Project Plan'!$V$2:$V$201,0))) -> 2.4 | C12: =IF($O12="","",INDEX('Project Plan'!$C$2:$C$201,MATCH($O12,'Project Plan'!$V$2:$V$201,0))) -> Execution | D12: =IF($O12="","",INDEX('Project Plan'!$D$2:$D$201,MATCH($O12,'Project Plan'!$V$2:$V$201,0))) -> Implement HIPAA-compliant processes | E12: =IF($O12="","",INDEX('Project Plan'!$G$2:$G$201,MATCH($O12,'Project Plan'!$V$2:$V$201,0))) -> Himansu Sekhar Bandha | F12: =IF($O12="","",INDEX('Project Plan'!$I$2:$I$201,MATCH($O12,'Project Plan'!$V$2:$V$201,0))) -> 45833 | G12: =IF($O12="","",INDEX('Project Plan'!$J$2:$J$201,MATCH($O12,'Project Plan'!$V$2:$V$201,0))) -> 45860 | H12: =IF($O12="","",INDEX('Project Plan'!$M$2:$M$201,MATCH($O12,'Project Plan'!$V$2:$V$201,0))) -> 46112 | I12: =IF($O12="","",INDEX('Project Plan'!$N$2:$N$201,MATCH($O12,'Project Plan'!$V$2:$V$201,0))) -> Completed | J12: =IF($O12="","",INDEX('Project Plan'!$O$2:$O$201,MATCH($O12,'Project Plan'!$V$2:$V$201,0))) -> 1 | K12: =IF($O12="","",INDEX('Project Plan'!$R$2:$R$201,MATCH($O12,'Project Plan'!$V$2:$V$201,0))) -> 46112 | L12: =IF($O12="","",INDEX('Project Plan'!$S$2:$S$201,MATCH($O12,'Project Plan'!$V$2:$V$201,0))) -> 0 | M12: =IF($O12="","",INDEX('Project Plan'!$T$2:$T$201,MATCH($O12,'Project Plan'!$V$2:$V$201,0))) -> Green | N12: =IF($O12="","",INDEX('Project Plan'!$U$2:$U$201,MATCH($O12,'Project Plan'!$V$2:$V$201,0))) -> 0 | O12: =IF(ROW()-1<=MAX('Project Plan'!$V$2:$V$201),ROW()-1,"") -> 11
A13: =IF($O13="","",INDEX('Project Plan'!$A$2:$A$201,MATCH($O13,'Project Plan'!$V$2:$V$201,0))) -> T-012 | B13: =IF($O13="","",INDEX('Project Plan'!$B$2:$B$201,MATCH($O13,'Project Plan'!$V$2:$V$201,0))) -> 2.5 | C13: =IF($O13="","",INDEX('Project Plan'!$C$2:$C$201,MATCH($O13,'Project Plan'!$V$2:$V$201,0))) -> Execution | D13: =IF($O13="","",INDEX('Project Plan'!$D$2:$D$201,MATCH($O13,'Project Plan'!$V$2:$V$201,0))) -> OpenDental API Integration | E13: =IF($O13="","",INDEX('Project Plan'!$G$2:$G$201,MATCH($O13,'Project Plan'!$V$2:$V$201,0))) -> Himansu Sekhar Bandha | F13: =IF($O13="","",INDEX('Project Plan'!$I$2:$I$201,MATCH($O13,'Project Plan'!$V$2:$V$201,0))) -> 45819 | G13: =IF($O13="","",INDEX('Project Plan'!$J$2:$J$201,MATCH($O13,'Project Plan'!$V$2:$V$201,0))) -> 45860 | H13: =IF($O13="","",INDEX('Project Plan'!$M$2:$M$201,MATCH($O13,'Project Plan'!$V$2:$V$201,0))) -> 46112 | I13: =IF($O13="","",INDEX('Project Plan'!$N$2:$N$201,MATCH($O13,'Project Plan'!$V$2:$V$201,0))) -> Completed | J13: =IF($O13="","",INDEX('Project Plan'!$O$2:$O$201,MATCH($O13,'Project Plan'!$V$2:$V$201,0))) -> 1 | K13: =IF($O13="","",INDEX('Project Plan'!$R$2:$R$201,MATCH($O13,'Project Plan'!$V$2:$V$201,0))) -> 46112 | L13: =IF($O13="","",INDEX('Project Plan'!$S$2:$S$201,MATCH($O13,'Project Plan'!$V$2:$V$201,0))) -> 0 | M13: =IF($O13="","",INDEX('Project Plan'!$T$2:$T$201,MATCH($O13,'Project Plan'!$V$2:$V$201,0))) -> Green | N13: =IF($O13="","",INDEX('Project Plan'!$U$2:$U$201,MATCH($O13,'Project Plan'!$V$2:$V$201,0))) -> 0 | O13: =IF(ROW()-1<=MAX('Project Plan'!$V$2:$V$201),ROW()-1,"") -> 12
... A201: =IF($O201="","",INDEX('Project Plan'!$A$2:$A$201,MATCH($O201,'Project Plan'!$V$2:$V$201,0))) | B201: =IF($O201="","",INDEX('Project Plan'!$B$2:$B$201,MATCH($O201,'Project Plan'!$V$2:$V$201,0))) | C201: =IF($O201="","",INDEX('Project Plan'!$C$2:$C$201,MATCH($O201,'Project Plan'!$V$2:$V$201,0))) | D201: =IF($O201="","",INDEX('Project Plan'!$D$2:$D$201,MATCH($O201,'Project Plan'!$V$2:$V$201,0))) | E201: =IF($O201="","",INDEX('Project Plan'!$G$2:$G$201,MATCH($O201,'Project Plan'!$V$2:$V$201,0))) | F201: =IF($O201="","",INDEX('Project Plan'!$I$2:$I$201,MATCH($O201,'Project Plan'!$V$2:$V$201,0))) | G201: =IF($O201="","",INDEX('Project Plan'!$J$2:$J$201,MATCH($O201,'Project Plan'!$V$2:$V$201,0))) | H201: =IF($O201="","",INDEX('Project Plan'!$M$2:$M$201,MATCH($O201,'Project Plan'!$V$2:$V$201,0))) | I201: =IF($O201="","",INDEX('Project Plan'!$N$2:$N$201,MATCH($O201,'Project Plan'!$V$2:$V$201,0))) | J201: =IF($O201="","",INDEX('Project Plan'!$O$2:$O$201,MATCH($O201,'Project Plan'!$V$2:$V$201,0))) | K201: =IF($O201="","",INDEX('Project Plan'!$R$2:$R$201,MATCH($O201,'Project Plan'!$V$2:$V$201,0))) | L201: =IF($O201="","",INDEX('Project Plan'!$S$2:$S$201,MATCH($O201,'Project Plan'!$V$2:$V$201,0))) | M201: =IF($O201="","",INDEX('Project Plan'!$T$2:$T$201,MATCH($O201,'Project Plan'!$V$2:$V$201,0))) | N201: =IF($O201="","",INDEX('Project Plan'!$U$2:$U$201,MATCH($O201,'Project Plan'!$V$2:$V$201,0))) | O201: =IF(ROW()-1<=MAX('Project Plan'!$V$2:$V$201),ROW()-1,"")

Sheet RAID Log
A1: RAID ID | B1: Type | C1: Category | D1: Impact Area | E1: Title | F1: Description | G1: Impact/Effect of the RAID | H1: Date Raised | I1: RAID Owner | J1: Impact Rating | K1: Initial Probability | L1: Severity | M1: Target Date | N1: Status | O1: Mitigation Strategy | P1: Next Update | Q1: Closed Date | R1: RAID Response/Plan | S1: Risk Seq
A2: 1 | B2: Risk | C2: Scope | D2: Schedule | E2: To improve the AI model's accuracy to achieve results | F2: To improve the AI model's accuracy to achieve results | H2: 46193 | I2: Manjunath Sirur, Andrew team | J2: Severe | K2: Severe | L2: High | M2: July 30 2025 | N2: Closed | O2: Mitigate | Q2: July 30 2025 | R2: Team is working to optimise the AI models. Detailed report to be shared by manju - ETA - 14 -Aug-2025
A3: 2 | B3: Issue | C3: Technical | D3: Schedule | E3: Team to work on the analysis for connecting the Open dental | F3: Team to work on the analysis for connecting the Open dental | H3: 45855 | I3: Andrew,Himansu | J3: Severe | K3: Severe | L3: High | M3: July 25 2025 | N3: Closed | O3: Accept | Q3: July 25 2025 | R3: Himansu has shared the details and 7, 8 action items to be completed
A4: 3 | B4: Issue | C4: Process | D4: Schedule | E4: To provide access to the Dr.Ibrahim for him to start early testing | F4: To provide access to the Dr.Ibrahim for him to start early testing | H4: 45855 | I4: Mani Chandana, Back End team | J4: Major | K4: Major | L4: High | M4: Aug 1 2025 | N4: Closed | O4: Avoid | Q4: Aug 1 2025 | R4: Team is working on setting up in separate environment .
A5: 4 | B5: Issue | C5: Security/Compliance | D5: Schedule | E5: Team to work on the cost on the sftp instance and provide an update on to Dr.Ibrahim | F5: Team to work on the cost on the sftp instance and provide an update on to Dr.Ibrahim | H5: 45859 | I5: Santhana and Andrew | J5: Moderate | K5: Moderate | L5: High | M5: July 25 2025 | N5: Closed | O5: Mitigate | Q5: July 25 2025 | R5: Andrew has shared the costing options and doctor confirmed to go ahead.
A6: 5 | B6: Issue | C6: Process | D6: Schedule | E6: Team to share the cost details related to change requests of additional scope. | F6: Team to share the cost details related to change requests of additional scope. | H6: 45859 | I6: Len Summa, Sai Siddarth | J6: Moderate | K6: Moderate | L6: High | M6: July 25 2025 | N6: Closed | O6: Accept | Q6: July 25 2025 | R6: Len and Siddarth is going to discuss with Dr and provide next updates.
A7: 6 | B7: Issue | C7: Security/Compliance | D7: Schedule | E7: Team to discuss in detail with Dr.Ibrahim about the account page,AI Page,Manual processing button ,notification settings | F7: Team to discuss in detail with Dr.Ibrahim about the account page,AI Page,Manual processing button ,notification settings | H7: 45859 | I7: Himansu | J7: Moderate | K7: Moderate | L7: High | M7: July 25 2025 | N7: Closed | O7: Avoid | Q7: July 25 2025 | R7: Call is completed and requirments clarifications are completed
A8: 7 | B8: Issue | C8: Stakeholder | D8: Schedule | E8: Need to share with doctor List of API and set up images for the Developer portal access | F8: Need to share with doctor List of API and set up images for the Developer portal access | H8: 45862 | I8: Andrew,Himansu | J8: Moderate | K8: Moderate | L8: Medium | M8: July 28 2025 | N8: Closed | O8: Mitigate | Q8: July 28 2025 | R8: Andrew and Himansu will share the list
A9: 8 | B9: Issue | C9: Process | D9: Schedule | E9: Need to share the document by correcting the images without patient data and to be slide presentation | F9: Need to share the document by correcting the images without patient data and to be slide presentation | H9: 45862 | I9: Himansu | J9: Minor | K9: Minor | L9: Medium | M9: July 28 2025 | N9: Closed | O9: Accept | Q9: July 28 2025 | R9: Himansu to update the details and share it
A10: 9 | B10: Issue | C10: Technical | D10: Schedule | E10: Need to share the tax ID validation steps from any website (IRS) and the format of tax ID to be corrected | F10: Need to share the tax ID validation steps from any website (IRS) and the format of tax ID to be corrected | H10: 45862 | I10: Himansu,Andrew | J10: Moderate | K10: Moderate | L10: Medium | M10: July 31 2025 | N10: Closed | O10: Avoid | Q10: July 31 2025 | R10: it was concluded no third party will be used
A11: 10 | B11: Issue | C11: Process | D11: Schedule | E11: Set of examples to be shared by Doctor by tax ID and picture how the clinic should look alike | F11: Set of examples to be shared by Doctor by tax ID and picture how the clinic should look alike | H11: 45862 | I11: Dr.Ibrahim | J11: Major | K11: Major | L11: Low | M11: July 25 2025 | N11: Closed | O11: Mitigate | Q11: July 25 2025 | R11: Doctor has shared requested details
A12: 11 | B12: Issue | C12: Process | D12: Schedule | E12: Team to get back on the email 2 way authentication | F12: Team to get back on the email 2 way authentication | H12: 45862 | I12: Andrew,Himansu | J12: Minor | K12: Minor | L12: Medium | M12: July 28 2025 | N12: Closed | O12: Accept | Q12: July 28 2025 | R12: Himansu and Andrew to discuss on the technical challenges
A13: 12 | B13: Issue | C13: Technical | D13: Schedule | E13: Smartsync needs to be added in email forgot password functionality and create new password should show up in screen | F13: Smartsync needs to be added in email forgot password functionality and create new password should show up in screen | H13: 45866 | I13: Himansu and Team | J13: Moderate | K13: Moderate | L13: Medium | M13: Aug 19 2025 | N13: Closed | O13: Avoid | Q13: Aug 19 2025 | R13: Team will be taking up as an enhancements and fix the UI changes in the current sprint and complete
A14: 13 | B14: Issue | C14: Technical | D14: Schedule | E14: All UI related changes will be incorporated in upcoming sprints Replace “Open Dental” with more general “PMS integration” in notification terminology Remove the dash in the Tax ID field label (use “TaxID”) for consistent formatting Reorder address input fields to follow U.S. conventions: Address → City → State → ZIP Code In the Add Location form: Display only the logged‑in admin’s name, not a dropdown In user/account edit screens: Make admin name and email fields read‑only, and non‑clickable | F14: All UI related changes will be incorporated in upcoming sprints Replace “Open Dental” with more general “PMS integration” in notification terminology Remove the dash in the Tax ID field label (use “TaxID”) for consistent formatting Reorder address input fields to follow U.S. conventions: Address → City → State → ZIP Code In the Add Location form: Display only the logged‑in admin’s name, not a dropdown In user/account edit screens: Make admin name and email fields read‑only, and non‑clickable | H14: 45866 | I14: Himansu and Team | J14: Moderate | K14: Moderate | L14: Medium | M14: Aug 19 2025 | N14: Closed | O14: Mitigate | Q14: Aug 19 2025 | R14: Team will be taking up as an enhancements and fix the UI changes in the current sprint complete
A15: 14 | B15: Issue | C15: Technical | D15: Schedule | E15: Design and streamline the workflow that links Ibrahim’s login to his assigned location within Smart Sync Dental, and clearly demonstrate how the connection is established. | F15: Design and streamline the workflow that links Ibrahim’s login to his assigned location within Smart Sync Dental, and clearly demonstrate how the connection is established. | H15: 45875 | I15: Andrew,Himansu | J15: Moderate | K15: Moderate | L15: High | M15: Aug 13 2025 | N15: Closed | O15: Accept | Q15: Aug 13 2025
A16: 15 | B16: Issue | C16: Quality | D16: Schedule | E16: Feedback from doctor in staging environment | F16: Feedback from doctor in staging environment | H16: 45880 | I16: Zapcom Team | J16: Moderate | K16: Moderate | L16: High | M16: Aug 19 2025 | N16: Closed | O16: Avoid | Q16: Aug 19 2025 | R16: Team to share the plan with doctor for the fixes
A17: 16 | B17: Issue | C17: Stakeholder | D17: Schedule | E17: Domain regards and BAA agreement | F17: Domain regards and BAA agreement | H17: 45880 | I17: Dr.Ibrahim and zapcom Infra team | J17: Moderate | K17: Moderate | L17: High | M17: Aug 30 2025 | N17: Closed | O17: Accept | Q17: Aug 30 2025 | R17: Team to share the required details with doctor and next steps detailed discussion will be planned
A18: 17 | B18: Issue | C18: Process | D18: Schedule | E18: A SES account needed for converting to production | F18: A SES account needed for converting to production | H18: 45881 | I18: Andrew ,Md shamim,Mani Chandana | J18: Moderate | K18: Moderate | L18: High | M18: Aug 19 2025 | N18: Closed | O18: Avoid | Q18: Aug 19 2025 | R18: A business needs to be submitted by dev team.
A19: 18 | B19: Dependency | C19: Quality | D19: Schedule
A20: 19 | B20: Dependency | C20: Security/Compliance | D20: Schedule
A21: 20 | B21: Dependency | C21: Technical | D21: Schedule
A22: 21 | B22: Dependency | C22: Stakeholder | D22: Schedule
A23: 22 | B23: Dependency | C23: Stakeholder | D23: Other
A24: 23 | B24: Dependency | C24: Technical | D24: Schedule
A25: 24 | B25: Dependency | C25: Technical | D25: Schedule
